<!DOCTYPE html><html><head><title>ConnectionRefusedError when trying to connect to Gremlin Server using Python</title></head><link href='style.css' rel='stylesheet' ><link rel='stylesheet' href='https://maxcdn.bootstrapcdn.com/font-awesome/4.7.0/css/font-awesome.min.css'><body><h2><a href='//stackoverflow.com/a/54824824'>ConnectionRefusedError when trying to connect to Gremlin Server using Python</a></h2><p class='feedback'></p><br /><pre style='border:1px solid black;border-radius:5px'><code><p>Inappropriately as answer instead of a comment due to lacking the privilege:
I got the very same exception stack but when having the gremlin server running.
The configuration is <code>==&gt;Configured localhost/127.0.0.1:8182</code> the line not working is <code>&gt;&gt;&gt; g = graph.traversal().withRemote(DriverRemoteConnection('ws://localhost:8182', 'g'))</code>. What else can be the problem here?</p>
</code></pre><p>Posted by <a href='https://stackoverflow.com/users/6205117'>CodeNStuff</a> (18) at 2019-02-22T10:16:16Z</p><p>Caught for</p>Contains Blacklisted Word - comment<br/>Ends with ?<br/>Low Length<br/>IntelliBL - -2.0<br/>Low Rep<br/></body></html>
